[2024-11-15T18:33:04.560+0000] {local_task_job_runner.py:123} INFO - ::group::Pre task execution logs
[2024-11-15T18:33:04.581+0000] {taskinstance.py:2613} INFO - Dependencies all met for dep_context=non-requeueable deps ti=<TaskInstance: brew-dag.nvalido scheduled__2024-11-14T07:00:00+00:00 [queued]>
[2024-11-15T18:33:04.594+0000] {taskinstance.py:2613} INFO - Dependencies all met for dep_context=requeueable deps ti=<TaskInstance: brew-dag.nvalido scheduled__2024-11-14T07:00:00+00:00 [queued]>
[2024-11-15T18:33:04.595+0000] {taskinstance.py:2866} INFO - Starting attempt 5 of 6
[2024-11-15T18:33:04.614+0000] {taskinstance.py:2889} INFO - Executing <Task(BashOperator): nvalido> on 2024-11-14 07:00:00+00:00
[2024-11-15T18:33:04.624+0000] {warnings.py:112} WARNING - /home/***/.local/lib/python3.12/site-packages/***/task/task_runner/standard_task_runner.py:70: DeprecationWarning: This process (pid=150) is multi-threaded, use of fork() may lead to deadlocks in the child.
  pid = os.fork()

[2024-11-15T18:33:04.626+0000] {standard_task_runner.py:72} INFO - Started process 152 to run task
[2024-11-15T18:33:04.626+0000] {standard_task_runner.py:104} INFO - Running: ['***', 'tasks', 'run', 'brew-dag', 'nvalido', 'scheduled__2024-11-14T07:00:00+00:00', '--job-id', '111', '--raw', '--subdir', 'DAGS_FOLDER/brew-dag.py', '--cfg-path', '/tmp/tmp6fn89j4c']
[2024-11-15T18:33:04.627+0000] {standard_task_runner.py:105} INFO - Job 111: Subtask nvalido
[2024-11-15T18:33:04.681+0000] {task_command.py:467} INFO - Running <TaskInstance: brew-dag.nvalido scheduled__2024-11-14T07:00:00+00:00 [running]> on host 6cae2946a8ad
[2024-11-15T18:33:04.779+0000] {taskinstance.py:3132} INFO - Exporting env vars: AIRFLOW_CTX_DAG_OWNER='***' AIRFLOW_CTX_DAG_ID='brew-dag' AIRFLOW_CTX_TASK_ID='nvalido' AIRFLOW_CTX_EXECUTION_DATE='2024-11-14T07:00:00+00:00' AIRFLOW_CTX_TRY_NUMBER='5' AIRFLOW_CTX_DAG_RUN_ID='scheduled__2024-11-14T07:00:00+00:00'
[2024-11-15T18:33:04.781+0000] {logging_mixin.py:190} INFO - Task instance is in running state
[2024-11-15T18:33:04.782+0000] {logging_mixin.py:190} INFO -  Previous state of the Task instance: queued
[2024-11-15T18:33:04.782+0000] {logging_mixin.py:190} INFO - Current task name:nvalido state:running start_date:2024-11-15 18:33:04.582557+00:00
[2024-11-15T18:33:04.783+0000] {logging_mixin.py:190} INFO - Dag name:brew-dag and current dag run status:running
[2024-11-15T18:33:04.784+0000] {taskinstance.py:731} INFO - ::endgroup::
[2024-11-15T18:33:04.785+0000] {subprocess.py:78} INFO - Tmp dir root location: /tmp
[2024-11-15T18:33:04.790+0000] {subprocess.py:88} INFO - Running command: ['/usr/bin/bash', '-c', "echo 'API not valid'; exit 1;"]
[2024-11-15T18:33:04.801+0000] {subprocess.py:99} INFO - Output:
[2024-11-15T18:33:04.803+0000] {subprocess.py:106} INFO - API not valid
[2024-11-15T18:33:04.806+0000] {subprocess.py:110} INFO - Command exited with return code 1
[2024-11-15T18:33:04.817+0000] {taskinstance.py:3311} ERROR - Task failed with exception
Traceback (most recent call last):
  File "/home/airflow/.local/lib/python3.12/site-packages/airflow/models/taskinstance.py", line 762, in _execute_task
    result = _execute_callable(context=context, **execute_callable_kwargs)
             ^^^^^^^^^^^^^^^^^^^^^^^^^^^^^^^^^^^^^^^^^^^^^^^^^^^^^^^^^^^^^
  File "/home/airflow/.local/lib/python3.12/site-packages/airflow/models/taskinstance.py", line 733, in _execute_callable
    return ExecutionCallableRunner(
           ^^^^^^^^^^^^^^^^^^^^^^^^
  File "/home/airflow/.local/lib/python3.12/site-packages/airflow/utils/operator_helpers.py", line 252, in run
    return self.func(*args, **kwargs)
           ^^^^^^^^^^^^^^^^^^^^^^^^^^
  File "/home/airflow/.local/lib/python3.12/site-packages/airflow/models/baseoperator.py", line 417, in wrapper
    return func(self, *args, **kwargs)
           ^^^^^^^^^^^^^^^^^^^^^^^^^^^
  File "/home/airflow/.local/lib/python3.12/site-packages/airflow/operators/bash.py", line 276, in execute
    raise AirflowException(
airflow.exceptions.AirflowException: Bash command failed. The command returned a non-zero exit code 1.
[2024-11-15T18:33:04.827+0000] {logging_mixin.py:190} INFO - Task instance in failure state
[2024-11-15T18:33:04.828+0000] {logging_mixin.py:190} INFO - Task start:2024-11-15 18:33:04.582557+00:00 end:2024-11-15 18:33:04.827111+00:00 duration:0.244554
[2024-11-15T18:33:04.829+0000] {logging_mixin.py:190} INFO - Task:<Task(BashOperator): nvalido> dag:<DAG: brew-dag> dagrun:<DagRun brew-dag @ 2024-11-14 07:00:00+00:00: scheduled__2024-11-14T07:00:00+00:00, state:running, queued_at: 2024-11-15 18:31:59.471923+00:00. externally triggered: False>
[2024-11-15T18:33:04.830+0000] {logging_mixin.py:190} INFO - Failure caused by Bash command failed. The command returned a non-zero exit code 1.
[2024-11-15T18:33:04.830+0000] {taskinstance.py:1225} INFO - Marking task as UP_FOR_RETRY. dag_id=brew-dag, task_id=nvalido, run_id=scheduled__2024-11-14T07:00:00+00:00, execution_date=20241114T070000, start_date=20241115T183304, end_date=20241115T183304
[2024-11-15T18:33:04.850+0000] {taskinstance.py:340} INFO - ::group::Post task execution logs
[2024-11-15T18:33:04.851+0000] {standard_task_runner.py:124} ERROR - Failed to execute job 111 for task nvalido (Bash command failed. The command returned a non-zero exit code 1.; 152)
Traceback (most recent call last):
  File "/home/airflow/.local/lib/python3.12/site-packages/airflow/task/task_runner/standard_task_runner.py", line 117, in _start_by_fork
    ret = args.func(args, dag=self.dag)
          ^^^^^^^^^^^^^^^^^^^^^^^^^^^^^
  File "/home/airflow/.local/lib/python3.12/site-packages/airflow/cli/cli_config.py", line 49, in command
    return func(*args, **kwargs)
           ^^^^^^^^^^^^^^^^^^^^^
  File "/home/airflow/.local/lib/python3.12/site-packages/airflow/utils/cli.py", line 116, in wrapper
    return f(*args, **kwargs)
           ^^^^^^^^^^^^^^^^^^
  File "/home/airflow/.local/lib/python3.12/site-packages/airflow/cli/commands/task_command.py", line 483, in task_run
    task_return_code = _run_task_by_selected_method(args, _dag, ti)
                       ^^^^^^^^^^^^^^^^^^^^^^^^^^^^^^^^^^^^^^^^^^^^
  File "/home/airflow/.local/lib/python3.12/site-packages/airflow/cli/commands/task_command.py", line 256, in _run_task_by_selected_method
    return _run_raw_task(args, ti)
           ^^^^^^^^^^^^^^^^^^^^^^^
  File "/home/airflow/.local/lib/python3.12/site-packages/airflow/cli/commands/task_command.py", line 341, in _run_raw_task
    return ti._run_raw_task(
           ^^^^^^^^^^^^^^^^^
  File "/home/airflow/.local/lib/python3.12/site-packages/airflow/utils/session.py", line 97, in wrapper
    return func(*args, session=session, **kwargs)
           ^^^^^^^^^^^^^^^^^^^^^^^^^^^^^^^^^^^^^^
  File "/home/airflow/.local/lib/python3.12/site-packages/airflow/models/taskinstance.py", line 3005, in _run_raw_task
    return _run_raw_task(
           ^^^^^^^^^^^^^^
  File "/home/airflow/.local/lib/python3.12/site-packages/airflow/models/taskinstance.py", line 273, in _run_raw_task
    TaskInstance._execute_task_with_callbacks(
  File "/home/airflow/.local/lib/python3.12/site-packages/airflow/models/taskinstance.py", line 3159, in _execute_task_with_callbacks
    result = self._execute_task(context, task_orig)
             ^^^^^^^^^^^^^^^^^^^^^^^^^^^^^^^^^^^^^^
  File "/home/airflow/.local/lib/python3.12/site-packages/airflow/models/taskinstance.py", line 3183, in _execute_task
    return _execute_task(self, context, task_orig)
           ^^^^^^^^^^^^^^^^^^^^^^^^^^^^^^^^^^^^^^^
  File "/home/airflow/.local/lib/python3.12/site-packages/airflow/models/taskinstance.py", line 762, in _execute_task
    result = _execute_callable(context=context, **execute_callable_kwargs)
             ^^^^^^^^^^^^^^^^^^^^^^^^^^^^^^^^^^^^^^^^^^^^^^^^^^^^^^^^^^^^^
  File "/home/airflow/.local/lib/python3.12/site-packages/airflow/models/taskinstance.py", line 733, in _execute_callable
    return ExecutionCallableRunner(
           ^^^^^^^^^^^^^^^^^^^^^^^^
  File "/home/airflow/.local/lib/python3.12/site-packages/airflow/utils/operator_helpers.py", line 252, in run
    return self.func(*args, **kwargs)
           ^^^^^^^^^^^^^^^^^^^^^^^^^^
  File "/home/airflow/.local/lib/python3.12/site-packages/airflow/models/baseoperator.py", line 417, in wrapper
    return func(self, *args, **kwargs)
           ^^^^^^^^^^^^^^^^^^^^^^^^^^^
  File "/home/airflow/.local/lib/python3.12/site-packages/airflow/operators/bash.py", line 276, in execute
    raise AirflowException(
airflow.exceptions.AirflowException: Bash command failed. The command returned a non-zero exit code 1.
[2024-11-15T18:33:04.883+0000] {local_task_job_runner.py:266} INFO - Task exited with return code 1
[2024-11-15T18:33:04.910+0000] {taskinstance.py:3895} INFO - 0 downstream tasks scheduled from follow-on schedule check
[2024-11-15T18:33:04.919+0000] {local_task_job_runner.py:245} INFO - ::endgroup::
