[2024-11-15T18:30:56.095+0000] {local_task_job_runner.py:123} INFO - ::group::Pre task execution logs
[2024-11-15T18:30:56.117+0000] {taskinstance.py:2613} INFO - Dependencies all met for dep_context=non-requeueable deps ti=<TaskInstance: brew-dag.nvalido scheduled__2024-11-14T07:00:00+00:00 [queued]>
[2024-11-15T18:30:56.130+0000] {taskinstance.py:2613} INFO - Dependencies all met for dep_context=requeueable deps ti=<TaskInstance: brew-dag.nvalido scheduled__2024-11-14T07:00:00+00:00 [queued]>
[2024-11-15T18:30:56.131+0000] {taskinstance.py:2866} INFO - Starting attempt 4 of 4
[2024-11-15T18:30:56.149+0000] {taskinstance.py:2889} INFO - Executing <Task(BashOperator): nvalido> on 2024-11-14 07:00:00+00:00
[2024-11-15T18:30:56.161+0000] {warnings.py:112} WARNING - /home/***/.local/lib/python3.12/site-packages/***/task/task_runner/standard_task_runner.py:70: DeprecationWarning: This process (pid=109) is multi-threaded, use of fork() may lead to deadlocks in the child.
  pid = os.fork()

[2024-11-15T18:30:56.163+0000] {standard_task_runner.py:72} INFO - Started process 111 to run task
[2024-11-15T18:30:56.164+0000] {standard_task_runner.py:104} INFO - Running: ['***', 'tasks', 'run', 'brew-dag', 'nvalido', 'scheduled__2024-11-14T07:00:00+00:00', '--job-id', '108', '--raw', '--subdir', 'DAGS_FOLDER/brew-dag.py', '--cfg-path', '/tmp/tmpp_4o3kqc']
[2024-11-15T18:30:56.165+0000] {standard_task_runner.py:105} INFO - Job 108: Subtask nvalido
[2024-11-15T18:30:56.221+0000] {task_command.py:467} INFO - Running <TaskInstance: brew-dag.nvalido scheduled__2024-11-14T07:00:00+00:00 [running]> on host 6cae2946a8ad
[2024-11-15T18:30:56.314+0000] {taskinstance.py:3132} INFO - Exporting env vars: AIRFLOW_CTX_DAG_EMAIL='nelsonlsn@outlook.com' AIRFLOW_CTX_DAG_OWNER='***' AIRFLOW_CTX_DAG_ID='brew-dag' AIRFLOW_CTX_TASK_ID='nvalido' AIRFLOW_CTX_EXECUTION_DATE='2024-11-14T07:00:00+00:00' AIRFLOW_CTX_TRY_NUMBER='4' AIRFLOW_CTX_DAG_RUN_ID='scheduled__2024-11-14T07:00:00+00:00'
[2024-11-15T18:30:56.315+0000] {logging_mixin.py:190} INFO - Task instance is in running state
[2024-11-15T18:30:56.316+0000] {logging_mixin.py:190} INFO -  Previous state of the Task instance: queued
[2024-11-15T18:30:56.317+0000] {logging_mixin.py:190} INFO - Current task name:nvalido state:running start_date:2024-11-15 18:30:56.118827+00:00
[2024-11-15T18:30:56.317+0000] {logging_mixin.py:190} INFO - Dag name:brew-dag and current dag run status:running
[2024-11-15T18:30:56.318+0000] {taskinstance.py:731} INFO - ::endgroup::
[2024-11-15T18:30:56.319+0000] {subprocess.py:78} INFO - Tmp dir root location: /tmp
[2024-11-15T18:30:56.321+0000] {subprocess.py:88} INFO - Running command: ['/usr/bin/bash', '-c', "echo 'API not valid'; exit 1;"]
[2024-11-15T18:30:56.337+0000] {subprocess.py:99} INFO - Output:
[2024-11-15T18:30:56.338+0000] {subprocess.py:106} INFO - API not valid
[2024-11-15T18:30:56.339+0000] {subprocess.py:110} INFO - Command exited with return code 1
[2024-11-15T18:30:56.351+0000] {taskinstance.py:3311} ERROR - Task failed with exception
Traceback (most recent call last):
  File "/home/airflow/.local/lib/python3.12/site-packages/airflow/models/taskinstance.py", line 762, in _execute_task
    result = _execute_callable(context=context, **execute_callable_kwargs)
             ^^^^^^^^^^^^^^^^^^^^^^^^^^^^^^^^^^^^^^^^^^^^^^^^^^^^^^^^^^^^^
  File "/home/airflow/.local/lib/python3.12/site-packages/airflow/models/taskinstance.py", line 733, in _execute_callable
    return ExecutionCallableRunner(
           ^^^^^^^^^^^^^^^^^^^^^^^^
  File "/home/airflow/.local/lib/python3.12/site-packages/airflow/utils/operator_helpers.py", line 252, in run
    return self.func(*args, **kwargs)
           ^^^^^^^^^^^^^^^^^^^^^^^^^^
  File "/home/airflow/.local/lib/python3.12/site-packages/airflow/models/baseoperator.py", line 417, in wrapper
    return func(self, *args, **kwargs)
           ^^^^^^^^^^^^^^^^^^^^^^^^^^^
  File "/home/airflow/.local/lib/python3.12/site-packages/airflow/operators/bash.py", line 276, in execute
    raise AirflowException(
airflow.exceptions.AirflowException: Bash command failed. The command returned a non-zero exit code 1.
[2024-11-15T18:30:56.356+0000] {logging_mixin.py:190} INFO - Task instance in failure state
[2024-11-15T18:30:56.357+0000] {logging_mixin.py:190} INFO - Task start:2024-11-15 18:30:56.118827+00:00 end:2024-11-15 18:30:56.355903+00:00 duration:0.237076
[2024-11-15T18:30:56.359+0000] {logging_mixin.py:190} INFO - Task:<Task(BashOperator): nvalido> dag:<DAG: brew-dag> dagrun:<DagRun brew-dag @ 2024-11-14 07:00:00+00:00: scheduled__2024-11-14T07:00:00+00:00, state:running, queued_at: 2024-11-15 18:19:01.369242+00:00. externally triggered: False>
[2024-11-15T18:30:56.360+0000] {logging_mixin.py:190} INFO - Failure caused by Bash command failed. The command returned a non-zero exit code 1.
[2024-11-15T18:30:56.361+0000] {taskinstance.py:1225} INFO - Marking task as FAILED. dag_id=brew-dag, task_id=nvalido, run_id=scheduled__2024-11-14T07:00:00+00:00, execution_date=20241114T070000, start_date=20241115T183056, end_date=20241115T183056
[2024-11-15T18:30:56.384+0000] {warnings.py:112} WARNING - /home/***/.local/lib/python3.12/site-packages/***/utils/email.py:155: RemovedInAirflow3Warning: Fetching SMTP credentials from configuration variables will be deprecated in a future release. Please set credentials using a connection instead.
  send_mime_email(e_from=mail_from, e_to=recipients, mime_msg=msg, conn_id=conn_id, dryrun=dryrun)

[2024-11-15T18:30:56.385+0000] {email.py:272} INFO - Email alerting: attempt 1
[2024-11-15T18:30:58.549+0000] {email.py:283} INFO - Sent an alert email to ['nelsonlsn@outlook.com']
[2024-11-15T18:31:00.803+0000] {taskinstance.py:1563} INFO - Executing callback at index 0: <lambda>
[2024-11-15T18:31:00.815+0000] {email.py:272} INFO - Email alerting: attempt 1
[2024-11-15T18:31:02.955+0000] {email.py:283} INFO - Sent an alert email to ['nelsonlsn@gmail.com']
[2024-11-15T18:31:05.130+0000] {taskinstance.py:340} INFO - ::group::Post task execution logs
[2024-11-15T18:31:05.131+0000] {standard_task_runner.py:124} ERROR - Failed to execute job 108 for task nvalido (Bash command failed. The command returned a non-zero exit code 1.; 111)
Traceback (most recent call last):
  File "/home/airflow/.local/lib/python3.12/site-packages/airflow/task/task_runner/standard_task_runner.py", line 117, in _start_by_fork
    ret = args.func(args, dag=self.dag)
          ^^^^^^^^^^^^^^^^^^^^^^^^^^^^^
  File "/home/airflow/.local/lib/python3.12/site-packages/airflow/cli/cli_config.py", line 49, in command
    return func(*args, **kwargs)
           ^^^^^^^^^^^^^^^^^^^^^
  File "/home/airflow/.local/lib/python3.12/site-packages/airflow/utils/cli.py", line 116, in wrapper
    return f(*args, **kwargs)
           ^^^^^^^^^^^^^^^^^^
  File "/home/airflow/.local/lib/python3.12/site-packages/airflow/cli/commands/task_command.py", line 483, in task_run
    task_return_code = _run_task_by_selected_method(args, _dag, ti)
                       ^^^^^^^^^^^^^^^^^^^^^^^^^^^^^^^^^^^^^^^^^^^^
  File "/home/airflow/.local/lib/python3.12/site-packages/airflow/cli/commands/task_command.py", line 256, in _run_task_by_selected_method
    return _run_raw_task(args, ti)
           ^^^^^^^^^^^^^^^^^^^^^^^
  File "/home/airflow/.local/lib/python3.12/site-packages/airflow/cli/commands/task_command.py", line 341, in _run_raw_task
    return ti._run_raw_task(
           ^^^^^^^^^^^^^^^^^
  File "/home/airflow/.local/lib/python3.12/site-packages/airflow/utils/session.py", line 97, in wrapper
    return func(*args, session=session, **kwargs)
           ^^^^^^^^^^^^^^^^^^^^^^^^^^^^^^^^^^^^^^
  File "/home/airflow/.local/lib/python3.12/site-packages/airflow/models/taskinstance.py", line 3005, in _run_raw_task
    return _run_raw_task(
           ^^^^^^^^^^^^^^
  File "/home/airflow/.local/lib/python3.12/site-packages/airflow/models/taskinstance.py", line 273, in _run_raw_task
    TaskInstance._execute_task_with_callbacks(
  File "/home/airflow/.local/lib/python3.12/site-packages/airflow/models/taskinstance.py", line 3159, in _execute_task_with_callbacks
    result = self._execute_task(context, task_orig)
             ^^^^^^^^^^^^^^^^^^^^^^^^^^^^^^^^^^^^^^
  File "/home/airflow/.local/lib/python3.12/site-packages/airflow/models/taskinstance.py", line 3183, in _execute_task
    return _execute_task(self, context, task_orig)
           ^^^^^^^^^^^^^^^^^^^^^^^^^^^^^^^^^^^^^^^
  File "/home/airflow/.local/lib/python3.12/site-packages/airflow/models/taskinstance.py", line 762, in _execute_task
    result = _execute_callable(context=context, **execute_callable_kwargs)
             ^^^^^^^^^^^^^^^^^^^^^^^^^^^^^^^^^^^^^^^^^^^^^^^^^^^^^^^^^^^^^
  File "/home/airflow/.local/lib/python3.12/site-packages/airflow/models/taskinstance.py", line 733, in _execute_callable
    return ExecutionCallableRunner(
           ^^^^^^^^^^^^^^^^^^^^^^^^
  File "/home/airflow/.local/lib/python3.12/site-packages/airflow/utils/operator_helpers.py", line 252, in run
    return self.func(*args, **kwargs)
           ^^^^^^^^^^^^^^^^^^^^^^^^^^
  File "/home/airflow/.local/lib/python3.12/site-packages/airflow/models/baseoperator.py", line 417, in wrapper
    return func(self, *args, **kwargs)
           ^^^^^^^^^^^^^^^^^^^^^^^^^^^
  File "/home/airflow/.local/lib/python3.12/site-packages/airflow/operators/bash.py", line 276, in execute
    raise AirflowException(
airflow.exceptions.AirflowException: Bash command failed. The command returned a non-zero exit code 1.
[2024-11-15T18:31:05.183+0000] {local_task_job_runner.py:266} INFO - Task exited with return code 1
[2024-11-15T18:31:05.205+0000] {taskinstance.py:3895} INFO - 0 downstream tasks scheduled from follow-on schedule check
[2024-11-15T18:31:05.209+0000] {local_task_job_runner.py:245} INFO - ::endgroup::
