[2024-11-12T23:03:45.166+0000] {local_task_job_runner.py:123} INFO - ::group::Pre task execution logs
[2024-11-12T23:03:45.395+0000] {taskinstance.py:2613} INFO - Dependencies all met for dep_context=non-requeueable deps ti=<TaskInstance: brew-dag.e_valido scheduled__2024-11-11T07:00:00+00:00 [queued]>
[2024-11-12T23:03:45.409+0000] {taskinstance.py:2613} INFO - Dependencies all met for dep_context=requeueable deps ti=<TaskInstance: brew-dag.e_valido scheduled__2024-11-11T07:00:00+00:00 [queued]>
[2024-11-12T23:03:45.422+0000] {taskinstance.py:2866} INFO - Starting attempt 2 of 3
[2024-11-12T23:03:45.447+0000] {taskinstance.py:2889} INFO - Executing <Task(BranchPythonOperator): e_valido> on 2024-11-11 07:00:00+00:00
[2024-11-12T23:03:45.463+0000] {standard_task_runner.py:104} INFO - Running: ['***', 'tasks', 'run', 'brew-dag', 'e_valido', 'scheduled__2024-11-11T07:00:00+00:00', '--job-id', '12', '--raw', '--subdir', 'DAGS_FOLDER/brew-dag.py', '--cfg-path', '/tmp/tmpqd8bl3i5']
[2024-11-12T23:03:45.465+0000] {standard_task_runner.py:105} INFO - Job 12: Subtask e_valido
[2024-11-12T23:03:45.468+0000] {warnings.py:112} WARNING - /home/***/.local/lib/python3.12/site-packages/***/task/task_runner/standard_task_runner.py:70: DeprecationWarning: This process (pid=455) is multi-threaded, use of fork() may lead to deadlocks in the child.
  pid = os.fork()

[2024-11-12T23:03:45.472+0000] {standard_task_runner.py:72} INFO - Started process 457 to run task
[2024-11-12T23:03:45.558+0000] {task_command.py:467} INFO - Running <TaskInstance: brew-dag.e_valido scheduled__2024-11-11T07:00:00+00:00 [running]> on host 60459ae802f2
[2024-11-12T23:03:45.701+0000] {taskinstance.py:3132} INFO - Exporting env vars: AIRFLOW_CTX_DAG_OWNER='***' AIRFLOW_CTX_DAG_ID='brew-dag' AIRFLOW_CTX_TASK_ID='e_valido' AIRFLOW_CTX_EXECUTION_DATE='2024-11-11T07:00:00+00:00' AIRFLOW_CTX_TRY_NUMBER='2' AIRFLOW_CTX_DAG_RUN_ID='scheduled__2024-11-11T07:00:00+00:00'
[2024-11-12T23:03:45.703+0000] {logging_mixin.py:190} INFO - Task instance is in running state
[2024-11-12T23:03:45.706+0000] {logging_mixin.py:190} INFO -  Previous state of the Task instance: queued
[2024-11-12T23:03:45.707+0000] {logging_mixin.py:190} INFO - Current task name:e_valido state:running start_date:2024-11-12 23:03:45.396943+00:00
[2024-11-12T23:03:45.709+0000] {logging_mixin.py:190} INFO - Dag name:brew-dag and current dag run status:running
[2024-11-12T23:03:45.710+0000] {taskinstance.py:731} INFO - ::endgroup::
[2024-11-12T23:03:45.711+0000] {baseoperator.py:416} WARNING - BranchPythonOperator.execute cannot be called outside TaskInstance!
[2024-11-12T23:03:45.713+0000] {taskinstance.py:3311} ERROR - Task failed with exception
Traceback (most recent call last):
  File "/home/airflow/.local/lib/python3.12/site-packages/airflow/models/taskinstance.py", line 762, in _execute_task
    result = _execute_callable(context=context, **execute_callable_kwargs)
             ^^^^^^^^^^^^^^^^^^^^^^^^^^^^^^^^^^^^^^^^^^^^^^^^^^^^^^^^^^^^^
  File "/home/airflow/.local/lib/python3.12/site-packages/airflow/models/taskinstance.py", line 733, in _execute_callable
    return ExecutionCallableRunner(
           ^^^^^^^^^^^^^^^^^^^^^^^^
  File "/home/airflow/.local/lib/python3.12/site-packages/airflow/utils/operator_helpers.py", line 252, in run
    return self.func(*args, **kwargs)
           ^^^^^^^^^^^^^^^^^^^^^^^^^^
  File "/home/airflow/.local/lib/python3.12/site-packages/airflow/models/baseoperator.py", line 417, in wrapper
    return func(self, *args, **kwargs)
           ^^^^^^^^^^^^^^^^^^^^^^^^^^^
  File "/home/airflow/.local/lib/python3.12/site-packages/airflow/operators/python.py", line 274, in execute
    return self.do_branch(context, super().execute(context))
                                   ^^^^^^^^^^^^^^^^^^^^^^^^
  File "/home/airflow/.local/lib/python3.12/site-packages/airflow/models/baseoperator.py", line 417, in wrapper
    return func(self, *args, **kwargs)
           ^^^^^^^^^^^^^^^^^^^^^^^^^^^
  File "/home/airflow/.local/lib/python3.12/site-packages/airflow/operators/python.py", line 238, in execute
    return_value = self.execute_callable()
                   ^^^^^^^^^^^^^^^^^^^^^^^
  File "/home/airflow/.local/lib/python3.12/site-packages/airflow/operators/python.py", line 256, in execute_callable
    return runner.run(*self.op_args, **self.op_kwargs)
           ^^^^^^^^^^^^^^^^^^^^^^^^^^^^^^^^^^^^^^^^^^^
  File "/home/airflow/.local/lib/python3.12/site-packages/airflow/utils/operator_helpers.py", line 252, in run
    return self.func(*args, **kwargs)
           ^^^^^^^^^^^^^^^^^^^^^^^^^^
  File "/opt/airflow/dags/brew-dag.py", line 31, in e_valido
    status_api = ti.xcom_pull(task_id = 'connect_api')
                 ^^^^^^^^^^^^^^^^^^^^^^^^^^^^^^^^^^^^^
  File "/home/airflow/.local/lib/python3.12/site-packages/airflow/utils/session.py", line 97, in wrapper
    return func(*args, session=session, **kwargs)
           ^^^^^^^^^^^^^^^^^^^^^^^^^^^^^^^^^^^^^^
TypeError: TaskInstance.xcom_pull() got an unexpected keyword argument 'task_id'
[2024-11-12T23:03:45.756+0000] {logging_mixin.py:190} INFO - Task instance in failure state
[2024-11-12T23:03:45.758+0000] {logging_mixin.py:190} INFO - Task start:2024-11-12 23:03:45.396943+00:00 end:2024-11-12 23:03:45.753559+00:00 duration:0.356616
[2024-11-12T23:03:45.759+0000] {logging_mixin.py:190} INFO - Task:<Task(BranchPythonOperator): e_valido> dag:<DAG: brew-dag> dagrun:<DagRun brew-dag @ 2024-11-11 07:00:00+00:00: scheduled__2024-11-11T07:00:00+00:00, state:running, queued_at: 2024-11-12 23:01:09.009496+00:00. externally triggered: False>
[2024-11-12T23:03:45.760+0000] {logging_mixin.py:190} INFO - Failure caused by TaskInstance.xcom_pull() got an unexpected keyword argument 'task_id'
[2024-11-12T23:03:45.762+0000] {taskinstance.py:1225} INFO - Marking task as UP_FOR_RETRY. dag_id=brew-dag, task_id=e_valido, run_id=scheduled__2024-11-11T07:00:00+00:00, execution_date=20241111T070000, start_date=20241112T230345, end_date=20241112T230345
[2024-11-12T23:03:45.790+0000] {taskinstance.py:340} INFO - ::group::Post task execution logs
[2024-11-12T23:03:45.791+0000] {standard_task_runner.py:124} ERROR - Failed to execute job 12 for task e_valido (TaskInstance.xcom_pull() got an unexpected keyword argument 'task_id'; 457)
Traceback (most recent call last):
  File "/home/airflow/.local/lib/python3.12/site-packages/airflow/task/task_runner/standard_task_runner.py", line 117, in _start_by_fork
    ret = args.func(args, dag=self.dag)
          ^^^^^^^^^^^^^^^^^^^^^^^^^^^^^
  File "/home/airflow/.local/lib/python3.12/site-packages/airflow/cli/cli_config.py", line 49, in command
    return func(*args, **kwargs)
           ^^^^^^^^^^^^^^^^^^^^^
  File "/home/airflow/.local/lib/python3.12/site-packages/airflow/utils/cli.py", line 116, in wrapper
    return f(*args, **kwargs)
           ^^^^^^^^^^^^^^^^^^
  File "/home/airflow/.local/lib/python3.12/site-packages/airflow/cli/commands/task_command.py", line 483, in task_run
    task_return_code = _run_task_by_selected_method(args, _dag, ti)
                       ^^^^^^^^^^^^^^^^^^^^^^^^^^^^^^^^^^^^^^^^^^^^
  File "/home/airflow/.local/lib/python3.12/site-packages/airflow/cli/commands/task_command.py", line 256, in _run_task_by_selected_method
    return _run_raw_task(args, ti)
           ^^^^^^^^^^^^^^^^^^^^^^^
  File "/home/airflow/.local/lib/python3.12/site-packages/airflow/cli/commands/task_command.py", line 341, in _run_raw_task
    return ti._run_raw_task(
           ^^^^^^^^^^^^^^^^^
  File "/home/airflow/.local/lib/python3.12/site-packages/airflow/utils/session.py", line 97, in wrapper
    return func(*args, session=session, **kwargs)
           ^^^^^^^^^^^^^^^^^^^^^^^^^^^^^^^^^^^^^^
  File "/home/airflow/.local/lib/python3.12/site-packages/airflow/models/taskinstance.py", line 3005, in _run_raw_task
    return _run_raw_task(
           ^^^^^^^^^^^^^^
  File "/home/airflow/.local/lib/python3.12/site-packages/airflow/models/taskinstance.py", line 273, in _run_raw_task
    TaskInstance._execute_task_with_callbacks(
  File "/home/airflow/.local/lib/python3.12/site-packages/airflow/models/taskinstance.py", line 3159, in _execute_task_with_callbacks
    result = self._execute_task(context, task_orig)
             ^^^^^^^^^^^^^^^^^^^^^^^^^^^^^^^^^^^^^^
  File "/home/airflow/.local/lib/python3.12/site-packages/airflow/models/taskinstance.py", line 3183, in _execute_task
    return _execute_task(self, context, task_orig)
           ^^^^^^^^^^^^^^^^^^^^^^^^^^^^^^^^^^^^^^^
  File "/home/airflow/.local/lib/python3.12/site-packages/airflow/models/taskinstance.py", line 762, in _execute_task
    result = _execute_callable(context=context, **execute_callable_kwargs)
             ^^^^^^^^^^^^^^^^^^^^^^^^^^^^^^^^^^^^^^^^^^^^^^^^^^^^^^^^^^^^^
  File "/home/airflow/.local/lib/python3.12/site-packages/airflow/models/taskinstance.py", line 733, in _execute_callable
    return ExecutionCallableRunner(
           ^^^^^^^^^^^^^^^^^^^^^^^^
  File "/home/airflow/.local/lib/python3.12/site-packages/airflow/utils/operator_helpers.py", line 252, in run
    return self.func(*args, **kwargs)
           ^^^^^^^^^^^^^^^^^^^^^^^^^^
  File "/home/airflow/.local/lib/python3.12/site-packages/airflow/models/baseoperator.py", line 417, in wrapper
    return func(self, *args, **kwargs)
           ^^^^^^^^^^^^^^^^^^^^^^^^^^^
  File "/home/airflow/.local/lib/python3.12/site-packages/airflow/operators/python.py", line 274, in execute
    return self.do_branch(context, super().execute(context))
                                   ^^^^^^^^^^^^^^^^^^^^^^^^
  File "/home/airflow/.local/lib/python3.12/site-packages/airflow/models/baseoperator.py", line 417, in wrapper
    return func(self, *args, **kwargs)
           ^^^^^^^^^^^^^^^^^^^^^^^^^^^
  File "/home/airflow/.local/lib/python3.12/site-packages/airflow/operators/python.py", line 238, in execute
    return_value = self.execute_callable()
                   ^^^^^^^^^^^^^^^^^^^^^^^
  File "/home/airflow/.local/lib/python3.12/site-packages/airflow/operators/python.py", line 256, in execute_callable
    return runner.run(*self.op_args, **self.op_kwargs)
           ^^^^^^^^^^^^^^^^^^^^^^^^^^^^^^^^^^^^^^^^^^^
  File "/home/airflow/.local/lib/python3.12/site-packages/airflow/utils/operator_helpers.py", line 252, in run
    return self.func(*args, **kwargs)
           ^^^^^^^^^^^^^^^^^^^^^^^^^^
  File "/opt/airflow/dags/brew-dag.py", line 31, in e_valido
    status_api = ti.xcom_pull(task_id = 'connect_api')
                 ^^^^^^^^^^^^^^^^^^^^^^^^^^^^^^^^^^^^^
  File "/home/airflow/.local/lib/python3.12/site-packages/airflow/utils/session.py", line 97, in wrapper
    return func(*args, session=session, **kwargs)
           ^^^^^^^^^^^^^^^^^^^^^^^^^^^^^^^^^^^^^^
TypeError: TaskInstance.xcom_pull() got an unexpected keyword argument 'task_id'
[2024-11-12T23:03:45.854+0000] {local_task_job_runner.py:266} INFO - Task exited with return code 1
[2024-11-12T23:03:45.884+0000] {taskinstance.py:3895} INFO - 0 downstream tasks scheduled from follow-on schedule check
[2024-11-12T23:03:45.892+0000] {local_task_job_runner.py:245} INFO - ::endgroup::
